<?xml version="1.0" encoding="UTF-8"?>
<!-- Generated by org.testng.reporters.JUnitReportReporter -->
<testsuite hostname="DESKTOP-NH3DV7T" failures="1" tests="1" name="RetryAnalyzer" time="0.049" errors="0" timestamp="2021-05-04T11:10:11 IST" skipped="0">
  <testcase classname="RetryAnalyzer" name="demo1" time="0.049">
    <failure message="null" type="java.lang.AssertionError">
      <![CDATA[java.lang.AssertionError: null
at org.testng.Assert.fail(Assert.java:99)
at org.testng.Assert.fail(Assert.java:106)
at RetryAnalyzer.demo1(RetryAnalyzer.java:11)
at java.base/jdk.internal.reflect.NativeMethodAccessorImpl.invoke0(Native Method)
at java.base/jdk.internal.reflect.NativeMethodAccessorImpl.invoke(NativeMethodAccessorImpl.java:64)
at java.base/jdk.internal.reflect.DelegatingMethodAccessorImpl.invoke(DelegatingMethodAccessorImpl.java:43)
at java.base/java.lang.reflect.Method.invoke(Method.java:564)
at org.testng.internal.MethodInvocationHelper.invokeMethod(MethodInvocationHelper.java:132)
at org.testng.internal.TestInvoker.invokeMethod(TestInvoker.java:599)
at org.testng.internal.TestInvoker.invokeTestMethod(TestInvoker.java:174)
at org.testng.internal.MethodRunner.runInSequence(MethodRunner.java:46)
at org.testng.internal.TestInvoker$MethodInvocationAgent.invoke(TestInvoker.java:822)
at org.testng.internal.TestInvoker.invokeTestMethods(TestInvoker.java:147)
at org.testng.internal.TestMethodWorker.invokeTestMethods(TestMethodWorker.java:146)
at org.testng.internal.TestMethodWorker.run(TestMethodWorker.java:128)
at java.base/java.util.ArrayList.forEach(ArrayList.java:1511)
at org.testng.TestRunner.privateRun(TestRunner.java:764)
at org.testng.TestRunner.run(TestRunner.java:585)
at org.testng.SuiteRunner.runTest(SuiteRunner.java:384)
at org.testng.SuiteRunner.runSequentially(SuiteRunner.java:378)
at org.testng.SuiteRunner.privateRun(SuiteRunner.java:337)
at org.testng.SuiteRunner.run(SuiteRunner.java:286)
at org.testng.SuiteRunnerWorker.runSuite(SuiteRunnerWorker.java:53)
at org.testng.SuiteRunnerWorker.run(SuiteRunnerWorker.java:96)
at org.testng.TestNG.runSuitesSequentially(TestNG.java:1218)
at org.testng.TestNG.runSuitesLocally(TestNG.java:1140)
at org.testng.TestNG.runSuites(TestNG.java:1069)
at org.testng.TestNG.run(TestNG.java:1037)
at org.testng.remote.AbstractRemoteTestNG.run(AbstractRemoteTestNG.java:115)
at org.testng.remote.RemoteTestNG.initAndRun(RemoteTestNG.java:251)
at org.testng.remote.RemoteTestNG.main(RemoteTestNG.java:77)
]]>
    </failure>
  </testcase> <!-- demo1 -->
  <system-out>
Test case 1 is running  </system-out>
</testsuite> <!-- RetryAnalyzer -->
